Workbook

Sheet Overview
A1: SELF-DIRECTED LEARNING AND PRACTICE PROJECT. Projects, clients, hours, rates and invoices are fictional. This is a simplified illustration of work-in-progress and revenue recognition concepts for learning. It is NOT accounting work, and accounting treatment decisions belong to an accountant.
A2: WIP, Billing and Revenue Recognition Tracker: Learning Project
A3: Understand work-in-progress, billable vs non-billable costs, and what to escalate
A5: Purpose | B5: Learn the vocabulary and the mechanics of project billing: how much work has been done, how much has been invoiced, what is not yet invoiced, and what the client still owes. Practice noticing what needs a project manager or an accountant.
A6: Sheets | B6: Glossary (plain-English terms), Projects (5 fictional contracts), Time_Costs (hours and expenses, billable or not), Billing (invoices and payments), Tracker (the WIP view), Escalation (what I would decide vs pass on), Learning_Plan (2-week plan with course options).
A7: As-of date | B7: 2026-09-30 (a month-end cut-off). Changing the date in Tracker cell B3 updates ages and flags.
A8: Two contract types | B8: Time and materials (T&M): revenue builds as billable hours and billable expenses accrue. Fixed price: revenue is estimated from progress, here billable hours divided by budget hours. Real accounting treatment depends on the contract and the accounting framework, which an accountant decides.
A9: Method used here | B9: Illustration only: T&M revenue = billable hours x rate + billable expenses. Fixed-price revenue = (billable hours / budget hours) x contract value, capped at 100%. Unbilled WIP = revenue earned minus invoiced (if positive). Billed in excess = invoiced minus revenue earned (if positive).
A10: Colour code | B10: Blue = typed input. Black = formula. Green = pulled from another sheet. Red or amber = something to look at.
A11: What this is not | B11: Not accounting experience. I do not set accounting policy, approve revenue or choose a method. The Escalation sheet shows what I would flag and to whom.

Sheet Tracker
A1: SELF-DIRECTED LEARNING AND PRACTICE PROJECT. Projects, clients, hours, rates and invoices are fictional. This is a simplified illustration of work-in-progress and revenue recognition concepts for learning. It is NOT accounting work, and accounting treatment decisions belong to an accountant.
A2: WIP and Billing Tracker
A3: As-of date: | B3: 46295
A5: Revenue earned to date ($) | C5: Invoiced to date ($) | F5: Unbilled WIP ($) | J5: Billed in excess ($) | M5: Paid ($) | O5: Outstanding AR ($)
A6: =N16 -> 266500 | C6: =O16 -> 233400 | F6: =P16 -> 41500 | J6: =Q16 -> 8400 | M6: =R16 -> 132000 | O6: =S16 -> 101400
A8: Fixed-price progress uses billable hours / budget hours as a simple stand-in for percentage of completion. The accountant would choose the real method.
A10: Project | B10: Name | C10: Contract type | D10: Billing rate ($/h) | E10: Contract value ($) | F10: Budget hours | G10: Billable hours | H10: Non-billable hours | I10: Total hours | J10: Billable labour value ($) | K10: Billable expenses ($) | L10: Non-billable expenses absorbed ($) | M10: % complete (fixed price) | N10: Revenue earned to date ($) | O10: Invoiced to date ($) | P10: Unbilled WIP ($) | Q10: Billed in excess ($) | R10: Paid ($) | S10: Outstanding AR ($) | T10: Days since last invoice | U10: Unbilled flag | V10: Billing-ahead flag | W10: Hours flag | X10: AR flag
A11: =Projects!A5 -> W-101 | B11: =Projects!B5 -> Compressor Station Tie-in | C11: =Projects!D5 -> Time & materials | D11: =IF(Projects!E5="","",Projects!E5) -> 115 | E11: =IF(Projects!F5="","",Projects!F5) | F11: =IF(Projects!G5="","",Projects!G5) | G11: =SUMIFS(Time_Costs!$F$5:$F$52,Time_Costs!$B$5:$B$52,A11,Time_Costs!$D$5:$D$52,"Labour",Time_Costs!$G$5:$G$52,"Y") -> 310 | H11: =SUMIFS(Time_Costs!$F$5:$F$52,Time_Costs!$B$5:$B$52,A11,Time_Costs!$D$5:$D$52,"Labour",Time_Costs!$G$5:$G$52,"N") -> 12 | I11: =G11+H11 -> 322 | J11: =IF(C11="Time & materials",G11*D11,0) -> 35650 | K11: =IF(C11="Time & materials",SUMIFS(Time_Costs!$H$5:$H$52,Time_Costs!$B$5:$B$52,A11,Time_Costs!$D$5:$D$52,"Expense",Time_Costs!$G$5:$G$52,"Y"),0) -> 3200 | L11: =SUMIFS(Time_Costs!$H$5:$H$52,Time_Costs!$B$5:$B$52,A11,Time_Costs!$D$5:$D$52,"Expense",Time_Costs!$G$5:$G$52,"N") -> 450 | M11: =IF(C11="Fixed price",MIN(1,G11/F11),"") | N11: =IF(C11="Fixed price",M11*E11,J11+K11) -> 38850 | O11: =SUMIFS(Billing!$D$5:$D$10,Billing!$C$5:$C$10,A11) -> 30000 | P11: =MAX(N11-O11,0) -> 8850 | Q11: =MAX(O11-N11,0) -> 0 | R11: =SUMIFS(Billing!$E$5:$E$10,Billing!$C$5:$C$10,A11) -> 0 | S11: =O11-R11 -> 30000 | T11: =IF(COUNTIFS(Billing!$C$5:$C$10,A11)=0,"None",$B$3-SUMPRODUCT(MAX((Billing!$C$5:$C$10=A11)*Billing!$B$5:$B$10))) -> 33 | U11: =IF(P11>0,IF(T11="None","UNBILLED: never invoiced",IF(T11>45,"UNBILLED: 45+ days since invoice","")),"") | V11: =IF(Q11>0,"BILLED AHEAD","") | W11: =IF(AND(C11="Fixed price",M11>=0.9),"NEAR BUDGET HOURS","") | X11: =IF(SUMIFS(Billing!$G$5:$G$10,Billing!$C$5:$C$10,A11,Billing!$H$5:$H$10,">30")>0,"AR 30+ DAYS","") -> AR 30+ DAYS
A12: =Projects!A6 -> W-102 | B12: =Projects!B6 -> Pipeline Integrity Dig Program | C12: =Projects!D6 -> Time & materials | D12: =IF(Projects!E6="","",Projects!E6) -> 98 | E12: =IF(Projects!F6="","",Projects!F6) | F12: =IF(Projects!G6="","",Projects!G6) | G12: =SUMIFS(Time_Costs!$F$5:$F$52,Time_Costs!$B$5:$B$52,A12,Time_Costs!$D$5:$D$52,"Labour",Time_Costs!$G$5:$G$52,"Y") -> 220 | H12: =SUMIFS(Time_Costs!$F$5:$F$52,Time_Costs!$B$5:$B$52,A12,Time_Costs!$D$5:$D$52,"Labour",Time_Costs!$G$5:$G$52,"N") -> 0 | I12: =G12+H12 -> 220 | J12: =IF(C12="Time & materials",G12*D12,0) -> 21560 | K12: =IF(C12="Time & materials",SUMIFS(Time_Costs!$H$5:$H$52,Time_Costs!$B$5:$B$52,A12,Time_Costs!$D$5:$D$52,"Expense",Time_Costs!$G$5:$G$52,"Y"),0) -> 1840 | L12: =SUMIFS(Time_Costs!$H$5:$H$52,Time_Costs!$B$5:$B$52,A12,Time_Costs!$D$5:$D$52,"Expense",Time_Costs!$G$5:$G$52,"N") -> 0 | M12: =IF(C12="Fixed price",MIN(1,G12/F12),"") | N12: =IF(C12="Fixed price",M12*E12,J12+K12) -> 23400 | O12: =SUMIFS(Billing!$D$5:$D$10,Billing!$C$5:$C$10,A12) -> 23400 | P12: =MAX(N12-O12,0) -> 0 | Q12: =MAX(O12-N12,0) -> 0 | R12: =SUMIFS(Billing!$E$5:$E$10,Billing!$C$5:$C$10,A12) -> 12000 | S12: =O12-R12 -> 11400 | T12: =IF(COUNTIFS(Billing!$C$5:$C$10,A12)=0,"None",$B$3-SUMPRODUCT(MAX((Billing!$C$5:$C$10=A12)*Billing!$B$5:$B$10))) -> 15 | U12: =IF(P12>0,IF(T12="None","UNBILLED: never invoiced",IF(T12>45,"UNBILLED: 45+ days since invoice","")),"") | V12: =IF(Q12>0,"BILLED AHEAD","") | W12: =IF(AND(C12="Fixed price",M12>=0.9),"NEAR BUDGET HOURS","") | X12: =IF(SUMIFS(Billing!$G$5:$G$10,Billing!$C$5:$C$10,A12,Billing!$H$5:$H$10,">30")>0,"AR 30+ DAYS","")
A13: =Projects!A7 -> W-103 | B13: =Projects!B7 -> Tank Farm Fabrication | C13: =Projects!D7 -> Fixed price | D13: =IF(Projects!E7="","",Projects!E7) | E13: =IF(Projects!F7="","",Projects!F7) -> 180000 | F13: =IF(Projects!G7="","",Projects!G7) -> 1500 | G13: =SUMIFS(Time_Costs!$F$5:$F$52,Time_Costs!$B$5:$B$52,A13,Time_Costs!$D$5:$D$52,"Labour",Time_Costs!$G$5:$G$52,"Y") -> 1380 | H13: =SUMIFS(Time_Costs!$F$5:$F$52,Time_Costs!$B$5:$B$52,A13,Time_Costs!$D$5:$D$52,"Labour",Time_Costs!$G$5:$G$52,"N") -> 60 | I13: =G13+H13 -> 1440 | J13: =IF(C13="Time & materials",G13*D13,0) -> 0 | K13: =IF(C13="Time & materials",SUMIFS(Time_Costs!$H$5:$H$52,Time_Costs!$B$5:$B$52,A13,Time_Costs!$D$5:$D$52,"Expense",Time_Costs!$G$5:$G$52,"Y"),0) -> 0 | L13: =SUMIFS(Time_Costs!$H$5:$H$52,Time_Costs!$B$5:$B$52,A13,Time_Costs!$D$5:$D$52,"Expense",Time_Costs!$G$5:$G$52,"N") -> 1100 | M13: =IF(C13="Fixed price",MIN(1,G13/F13),"") -> 0.92 | N13: =IF(C13="Fixed price",M13*E13,J13+K13) -> 165600 | O13: =SUMIFS(Billing!$D$5:$D$10,Billing!$C$5:$C$10,A13) -> 150000 | P13: =MAX(N13-O13,0) -> 15600 | Q13: =MAX(O13-N13,0) -> 0 | R13: =SUMIFS(Billing!$E$5:$E$10,Billing!$C$5:$C$10,A13) -> 90000 | S13: =O13-R13 -> 60000 | T13: =IF(COUNTIFS(Billing!$C$5:$C$10,A13)=0,"None",$B$3-SUMPRODUCT(MAX((Billing!$C$5:$C$10=A13)*Billing!$B$5:$B$10))) -> 20 | U13: =IF(P13>0,IF(T13="None","UNBILLED: never invoiced",IF(T13>45,"UNBILLED: 45+ days since invoice","")),"") | V13: =IF(Q13>0,"BILLED AHEAD","") | W13: =IF(AND(C13="Fixed price",M13>=0.9),"NEAR BUDGET HOURS","") -> NEAR BUDGET HOURS | X13: =IF(SUMIFS(Billing!$G$5:$G$10,Billing!$C$5:$C$10,A13,Billing!$H$5:$H$10,">30")>0,"AR 30+ DAYS","")
A14: =Projects!A8 -> W-104 | B14: =Projects!B8 -> Site Remediation Support | C14: =Projects!D8 -> Time & materials | D14: =IF(Projects!E8="","",Projects!E8) -> 105 | E14: =IF(Projects!F8="","",Projects!F8) | F14: =IF(Projects!G8="","",Projects!G8) | G14: =SUMIFS(Time_Costs!$F$5:$F$52,Time_Costs!$B$5:$B$52,A14,Time_Costs!$D$5:$D$52,"Labour",Time_Costs!$G$5:$G$52,"Y") -> 140 | H14: =SUMIFS(Time_Costs!$F$5:$F$52,Time_Costs!$B$5:$B$52,A14,Time_Costs!$D$5:$D$52,"Labour",Time_Costs!$G$5:$G$52,"N") -> 28 | I14: =G14+H14 -> 168 | J14: =IF(C14="Time & materials",G14*D14,0) -> 14700 | K14: =IF(C14="Time & materials",SUMIFS(Time_Costs!$H$5:$H$52,Time_Costs!$B$5:$B$52,A14,Time_Costs!$D$5:$D$52,"Expense",Time_Costs!$G$5:$G$52,"Y"),0) -> 2350 | L14: =SUMIFS(Time_Costs!$H$5:$H$52,Time_Costs!$B$5:$B$52,A14,Time_Costs!$D$5:$D$52,"Expense",Time_Costs!$G$5:$G$52,"N") -> 0 | M14: =IF(C14="Fixed price",MIN(1,G14/F14),"") | N14: =IF(C14="Fixed price",M14*E14,J14+K14) -> 17050 | O14: =SUMIFS(Billing!$D$5:$D$10,Billing!$C$5:$C$10,A14) -> 0 | P14: =MAX(N14-O14,0) -> 17050 | Q14: =MAX(O14-N14,0) -> 0 | R14: =SUMIFS(Billing!$E$5:$E$10,Billing!$C$5:$C$10,A14) -> 0 | S14: =O14-R14 -> 0 | T14: =IF(COUNTIFS(Billing!$C$5:$C$10,A14)=0,"None",$B$3-SUMPRODUCT(MAX((Billing!$C$5:$C$10=A14)*Billing!$B$5:$B$10))) -> None | U14: =IF(P14>0,IF(T14="None","UNBILLED: never invoiced",IF(T14>45,"UNBILLED: 45+ days since invoice","")),"") -> UNBILLED: never invoiced | V14: =IF(Q14>0,"BILLED AHEAD","") | W14: =IF(AND(C14="Fixed price",M14>=0.9),"NEAR BUDGET HOURS","") | X14: =IF(SUMIFS(Billing!$G$5:$G$10,Billing!$C$5:$C$10,A14,Billing!$H$5:$H$10,">30")>0,"AR 30+ DAYS","")
A15: =Projects!A9 -> W-105 | B15: =Projects!B9 -> Plant Turnaround Planning | C15: =Projects!D9 -> Fixed price | D15: =IF(Projects!E9="","",Projects!E9) | E15: =IF(Projects!F9="","",Projects!F9) -> 72000 | F15: =IF(Projects!G9="","",Projects!G9) -> 600 | G15: =SUMIFS(Time_Costs!$F$5:$F$52,Time_Costs!$B$5:$B$52,A15,Time_Costs!$D$5:$D$52,"Labour",Time_Costs!$G$5:$G$52,"Y") -> 180 | H15: =SUMIFS(Time_Costs!$F$5:$F$52,Time_Costs!$B$5:$B$52,A15,Time_Costs!$D$5:$D$52,"Labour",Time_Costs!$G$5:$G$52,"N") -> 0 | I15: =G15+H15 -> 180 | J15: =IF(C15="Time & materials",G15*D15,0) -> 0 | K15: =IF(C15="Time & materials",SUMIFS(Time_Costs!$H$5:$H$52,Time_Costs!$B$5:$B$52,A15,Time_Costs!$D$5:$D$52,"Expense",Time_Costs!$G$5:$G$52,"Y"),0) -> 0 | L15: =SUMIFS(Time_Costs!$H$5:$H$52,Time_Costs!$B$5:$B$52,A15,Time_Costs!$D$5:$D$52,"Expense",Time_Costs!$G$5:$G$52,"N") -> 300 | M15: =IF(C15="Fixed price",MIN(1,G15/F15),"") -> 0.3 | N15: =IF(C15="Fixed price",M15*E15,J15+K15) -> 21600 | O15: =SUMIFS(Billing!$D$5:$D$10,Billing!$C$5:$C$10,A15) -> 30000 | P15: =MAX(N15-O15,0) -> 0 | Q15: =MAX(O15-N15,0) -> 8400 | R15: =SUMIFS(Billing!$E$5:$E$10,Billing!$C$5:$C$10,A15) -> 30000 | S15: =O15-R15 -> 0 | T15: =IF(COUNTIFS(Billing!$C$5:$C$10,A15)=0,"None",$B$3-SUMPRODUCT(MAX((Billing!$C$5:$C$10=A15)*Billing!$B$5:$B$10))) -> 49 | U15: =IF(P15>0,IF(T15="None","UNBILLED: never invoiced",IF(T15>45,"UNBILLED: 45+ days since invoice","")),"") | V15: =IF(Q15>0,"BILLED AHEAD","") -> BILLED AHEAD | W15: =IF(AND(C15="Fixed price",M15>=0.9),"NEAR BUDGET HOURS","") | X15: =IF(SUMIFS(Billing!$G$5:$G$10,Billing!$C$5:$C$10,A15,Billing!$H$5:$H$10,">30")>0,"AR 30+ DAYS","")
A16: Total | G16: =SUM(G11:G15) -> 2230 | H16: =SUM(H11:H15) -> 100 | I16: =SUM(I11:I15) -> 2330 | J16: =SUM(J11:J15) -> 71910 | K16: =SUM(K11:K15) -> 7390 | L16: =SUM(L11:L15) -> 1850 | N16: =SUM(N11:N15) -> 266500 | O16: =SUM(O11:O15) -> 233400 | P16: =SUM(P11:P15) -> 41500 | Q16: =SUM(Q11:Q15) -> 8400 | R16: =SUM(R11:R15) -> 132000 | S16: =SUM(S11:S15) -> 101400
A17: Check: revenue earned = invoiced + unbilled WIP - billed in excess | N17: =IF(ABS(N16-(O16+P16-Q16))<0.5,"OK","DIFFERENCE") -> OK
A18: Check: invoiced total = Billing sheet total | N18: =IF(ABS(O16-Billing!D11)<0.5,"OK","DIFFERENCE") -> OK
A19: Check: hours total = Time_Costs total | N19: =IF(ABS(I16-Time_Costs!F53)<0.01,"OK","DIFFERENCE") -> OK

Sheet Glossary
A1: SELF-DIRECTED LEARNING AND PRACTICE PROJECT. Projects, clients, hours, rates and invoices are fictional. This is a simplified illustration of work-in-progress and revenue recognition concepts for learning. It is NOT accounting work, and accounting treatment decisions belong to an accountant.
A2: Glossary (plain English)
A3: Written for my own learning. Definitions are simplified; the accountant's policy governs.
A4: Term | B4: Plain-English meaning | C4: Where it shows up in this workbook | D4: Mine to handle, or escalate?
A5: Billable | B5: Work or cost the client agrees to pay for under the contract. | C5: Billable? column on Time_Costs | D5: Check the flag against the contract; escalate if unclear
A6: Non-billable | B6: Work or cost the company absorbs (rework, internal training, overhead). It is not invoiced to the client. | C6: Billable? = N | D6: Flag unusual amounts to the PM
A7: Time and materials (T&M) | B7: The client pays for hours at agreed rates plus approved expenses. | C7: W-101, W-102, W-104 | D7: Apply rates from the contract; escalate rate questions
A8: Fixed price | B8: The client pays an agreed price for a defined scope regardless of hours worked. | C8: W-103, W-105 | D8: Escalate progress and forecast questions
A9: Work in progress (WIP) | B9: Work performed on a project that has not yet been fully invoiced. In practice it can mean the unbilled value, or the costs built up on open jobs. | C9: Unbilled WIP column | D9: Report the number; accountant owns the treatment
A10: Unbilled WIP (unbilled revenue) | B10: Revenue earned to date minus amounts invoiced. Accountants may call it a contract asset or unbilled revenue. | C10: Tracker, Unbilled WIP | D10: Flag aging to PM; accountant books it
A11: Billed in excess (deferred revenue) | B11: Amounts invoiced ahead of the work done. Accountants may call it deferred revenue or a contract liability. | C11: Tracker, Billed in excess | D11: Escalate to accountant
A12: Revenue recognition | B12: The rules for when revenue is counted: as work is done or when control passes, not simply when an invoice is sent or cash arrives. | C12: Tracker, Revenue earned to date | D12: Accountant decides
A13: Percentage of completion | B13: One way to estimate progress on a fixed-price job. Here: billable hours divided by budget hours. Other methods use costs or milestones. | C13: Tracker, % complete | D13: PM supplies progress; accountant chooses the method
A14: Accrual | B14: Recording revenue or cost when it is earned or incurred, even if the invoice or payment comes later. | C14: Unbilled WIP is an accrual idea | D14: Accountant
A15: Cut-off | B15: The date that separates one period from the next. Work done by the cut-off belongs in that period. | C15: As-of date 2026-09-30 | D15: Follow the month-end calendar; escalate late items
... A23: Retainage / holdback | B23: A portion of an invoice the client withholds until a milestone or completion. | C23: Not modelled | D23: Ask accountant how to record

Sheet Projects
A1: SELF-DIRECTED LEARNING AND PRACTICE PROJECT. Projects, clients, hours, rates and invoices are fictional. This is a simplified illustration of work-in-progress and revenue recognition concepts for learning. It is NOT accounting work, and accounting treatment decisions belong to an accountant.
A2: Projects (fictional)
A4: Project | B4: Name | C4: Client | D4: Contract type | E4: Billing rate ($/h, T&M) | F4: Contract value ($, fixed price) | G4: Budget hours (fixed price)
A5: W-101 | B5: Compressor Station Tie-in | C5: Client A (fictional) | D5: Time & materials | E5: 115
A6: W-102 | B6: Pipeline Integrity Dig Program | C6: Client B (fictional) | D6: Time & materials | E6: 98
A7: W-103 | B7: Tank Farm Fabrication | C7: Client C (fictional) | D7: Fixed price | F7: 180000 | G7: 1500
A8: W-104 | B8: Site Remediation Support | C8: Client D (fictional) | D8: Time & materials | E8: 105
A9: W-105 | B9: Plant Turnaround Planning | C9: Client E (fictional) | D9: Fixed price | F9: 72000 | G9: 600

Sheet Time_Costs
A1: SELF-DIRECTED LEARNING AND PRACTICE PROJECT. Projects, clients, hours, rates and invoices are fictional. This is a simplified illustration of work-in-progress and revenue recognition concepts for learning. It is NOT accounting work, and accounting treatment decisions belong to an accountant.
A2: Hours and expenses
A4: Date | B4: Project | C4: Person / role | D4: Type | E4: Description | F4: Hours | G4: Billable? (Y/N) | H4: Expense amount ($) | I4: Project name
A5: 46241 | B5: W-101 | C5: Safety Advisor | D5: Labour | E5: Weekly time, billable | F5: 37 | G5: Y | I5: =INDEX(Projects!$B$5:$B$9,MATCH(B5,Projects!$A$5:$A$9,0)) -> Compressor Station Tie-in
A6: 46241 | B6: W-101 | C6: Project Coordinator | D6: Labour | E6: Weekly time, billable | F6: 40.5 | G6: Y | I6: =INDEX(Projects!$B$5:$B$9,MATCH(B6,Projects!$A$5:$A$9,0)) -> Compressor Station Tie-in
A7: 46241 | B7: W-101 | C7: Project Coordinator | D7: Labour | E7: Weekly time, billable | F7: 28.5 | G7: Y | I7: =INDEX(Projects!$B$5:$B$9,MATCH(B7,Projects!$A$5:$A$9,0)) -> Compressor Station Tie-in
A8: 46241 | B8: W-102 | C8: Project Coordinator | D8: Labour | E8: Weekly time, billable | F8: 34 | G8: Y | I8: =INDEX(Projects!$B$5:$B$9,MATCH(B8,Projects!$A$5:$A$9,0)) -> Pipeline Integrity Dig Program
A9: 46241 | B9: W-103 | C9: Safety Advisor | D9: Labour | E9: Weekly time, billable | F9: 71.5 | G9: Y | I9: =INDEX(Projects!$B$5:$B$9,MATCH(B9,Projects!$A$5:$A$9,0)) -> Tank Farm Fabrication
A10: 46241 | B10: W-103 | C10: Project Coordinator | D10: Labour | E10: Weekly time, billable | F10: 84 | G10: Y | I10: =INDEX(Projects!$B$5:$B$9,MATCH(B10,Projects!$A$5:$A$9,0)) -> Tank Farm Fabrication
A11: 46241 | B11: W-104 | C11: Field Supervisor | D11: Labour | E11: Weekly time, billable | F11: 45.5 | G11: Y | I11: =INDEX(Projects!$B$5:$B$9,MATCH(B11,Projects!$A$5:$A$9,0)) -> Site Remediation Support
A12: 46241 | B12: W-105 | C12: Project Coordinator | D12: Labour | E12: Weekly time, billable | F12: 42.5 | G12: Y | I12: =INDEX(Projects!$B$5:$B$9,MATCH(B12,Projects!$A$5:$A$9,0)) -> Plant Turnaround Planning
A13: 46248 | B13: W-102 | C13: Safety Advisor | D13: Labour | E13: Weekly time, billable | F13: 38.5 | G13: Y | I13: =INDEX(Projects!$B$5:$B$9,MATCH(B13,Projects!$A$5:$A$9,0)) -> Pipeline Integrity Dig Program
A14: 46248 | B14: W-103 | C14: Estimator | D14: Labour | E14: Weekly time, billable | F14: 67 | G14: Y | I14: =INDEX(Projects!$B$5:$B$9,MATCH(B14,Projects!$A$5:$A$9,0)) -> Tank Farm Fabrication
A15: 46248 | B15: W-103 | C15: Project Coordinator | D15: Labour | E15: Rework / internal training, not billable | F15: 30.5 | G15: N | I15: =INDEX(Projects!$B$5:$B$9,MATCH(B15,Projects!$A$5:$A$9,0)) -> Tank Farm Fabrication
A16: 46248 | B16: W-104 | C16: Project Coordinator | D16: Labour | E16: Weekly time, billable | F16: 22 | G16: Y | I16: =INDEX(Projects!$B$5:$B$9,MATCH(B16,Projects!$A$5:$A$9,0)) -> Site Remediation Support
A17: 46248 | B17: W-105 | C17: Safety Advisor | D17: Labour | E17: Weekly time, billable | F17: 44.5 | G17: Y | I17: =INDEX(Projects!$B$5:$B$9,MATCH(B17,Projects!$A$5:$A$9,0)) -> Plant Turnaround Planning
A18: 46254 | B18: W-101 | C18: n/a | D18: Expense | E18: Crane mat rental, re-billed at cost | G18: Y | H18: 3200 | I18: =INDEX(Projects!$B$5:$B$9,MATCH(B18,Projects!$A$5:$A$9,0)) -> Compressor Station Tie-in
A19: 46255 | B19: W-101 | C19: Project Coordinator | D19: Labour | E19: Weekly time, billable | F19: 36.5 | G19: Y | I19: =INDEX(Projects!$B$5:$B$9,MATCH(B19,Projects!$A$5:$A$9,0)) -> Compressor Station Tie-in
A20: 46255 | B20: W-101 | C20: Project Coordinator | D20: Labour | E20: Weekly time, billable | F20: 51 | G20: Y | I20: =INDEX(Projects!$B$5:$B$9,MATCH(B20,Projects!$A$5:$A$9,0)) -> Compressor Station Tie-in
A21: 46255 | B21: W-103 | C21: Estimator | D21: Labour | E21: Weekly time, billable | F21: 70 | G21: Y | I21: =INDEX(Projects!$B$5:$B$9,MATCH(B21,Projects!$A$5:$A$9,0)) -> Tank Farm Fabrication
A22: 46255 | B22: W-103 | C22: Safety Advisor | D22: Labour | E22: Weekly time, billable | F22: 127.5 | G22: Y | I22: =INDEX(Projects!$B$5:$B$9,MATCH(B22,Projects!$A$5:$A$9,0)) -> Tank Farm Fabrication
A23: 46255 | B23: W-103 | C23: Estimator | D23: Labour | E23: Rework / internal training, not billable | F23: 13.5 | G23: N | I23: =INDEX(Projects!$B$5:$B$9,MATCH(B23,Projects!$A$5:$A$9,0)) -> Tank Farm Fabrication
A24: 46255 | B24: W-105 | C24: Estimator | D24: Labour | E24: Weekly time, billable | F24: 25 | G24: Y | I24: =INDEX(Projects!$B$5:$B$9,MATCH(B24,Projects!$A$5:$A$9,0)) -> Plant Turnaround Planning
A25: 46262 | B25: W-101 | C25: Estimator | D25: Labour | E25: Weekly time, billable | F25: 38 | G25: Y | I25: =INDEX(Projects!$B$5:$B$9,MATCH(B25,Projects!$A$5:$A$9,0)) -> Compressor Station Tie-in
A26: 46262 | B26: W-102 | C26: Field Supervisor | D26: Labour | E26: Weekly time, billable | F26: 37.5 | G26: Y | I26: =INDEX(Projects!$B$5:$B$9,MATCH(B26,Projects!$A$5:$A$9,0)) -> Pipeline Integrity Dig Program
A27: 46262 | B27: W-102 | C27: n/a | D27: Expense | E27: Travel and lodging, client site | G27: Y | H27: 1840 | I27: =INDEX(Projects!$B$5:$B$9,MATCH(B27,Projects!$A$5:$A$9,0)) -> Pipeline Integrity Dig Program
A28: 46262 | B28: W-103 | C28: Project Coordinator | D28: Labour | E28: Weekly time, billable | F28: 125.5 | G28: Y | I28: =INDEX(Projects!$B$5:$B$9,MATCH(B28,Projects!$A$5:$A$9,0)) -> Tank Farm Fabrication
A29: 46262 | B29: W-103 | C29: Project Coordinator | D29: Labour | E29: Weekly time, billable | F29: 83 | G29: Y | I29: =INDEX(Projects!$B$5:$B$9,MATCH(B29,Projects!$A$5:$A$9,0)) -> Tank Farm Fabrication
A30: 46262 | B30: W-104 | C30: Estimator | D30: Labour | E30: Weekly time, billable | F30: 39.5 | G30: Y | I30: =INDEX(Projects!$B$5:$B$9,MATCH(B30,Projects!$A$5:$A$9,0)) -> Site Remediation Support
A31: 46262 | B31: W-105 | C31: Estimator | D31: Labour | E31: Weekly time, billable | F31: 43.5 | G31: Y | I31: =INDEX(Projects!$B$5:$B$9,MATCH(B31,Projects!$A$5:$A$9,0)) -> Plant Turnaround Planning
A32: 46267 | B32: W-105 | C32: n/a | D32: Expense | E32: Planning software licence | G32: N | H32: 300 | I32: =INDEX(Projects!$B$5:$B$9,MATCH(B32,Projects!$A$5:$A$9,0)) -> Plant Turnaround Planning
A33: 46269 | B33: W-101 | C33: n/a | D33: Expense | E33: Office printing and supplies | G33: N | H33: 450 | I33: =INDEX(Projects!$B$5:$B$9,MATCH(B33,Projects!$A$5:$A$9,0)) -> Compressor Station Tie-in
A34: 46269 | B34: W-102 | C34: Field Supervisor | D34: Labour | E34: Weekly time, billable | F34: 34.5 | G34: Y | I34: =INDEX(Projects!$B$5:$B$9,MATCH(B34,Projects!$A$5:$A$9,0)) -> Pipeline Integrity Dig Program
A35: 46269 | B35: W-103 | C35: Field Supervisor | D35: Labour | E35: Weekly time, billable | F35: 91 | G35: Y | I35: =INDEX(Projects!$B$5:$B$9,MATCH(B35,Projects!$A$5:$A$9,0)) -> Tank Farm Fabrication
A36: 46269 | B36: W-103 | C36: Field Supervisor | D36: Labour | E36: Weekly time, billable | F36: 123.5 | G36: Y | I36: =INDEX(Projects!$B$5:$B$9,MATCH(B36,Projects!$A$5:$A$9,0)) -> Tank Farm Fabrication
A37: 46276 | B37: W-103 | C37: Project Coordinator | D37: Labour | E37: Weekly time, billable | F37: 75 | G37: Y | I37: =INDEX(Projects!$B$5:$B$9,MATCH(B37,Projects!$A$5:$A$9,0)) -> Tank Farm Fabrication
A38: 46276 | B38: W-103 | C38: n/a | D38: Expense | E38: Scrap steel from cutting error | G38: N | H38: 1100 | I38: =INDEX(Projects!$B$5:$B$9,MATCH(B38,Projects!$A$5:$A$9,0)) -> Tank Farm Fabrication
A39: 46276 | B39: W-104 | C39: Safety Advisor | D39: Labour | E39: Weekly time, billable | F39: 33 | G39: Y | I39: =INDEX(Projects!$B$5:$B$9,MATCH(B39,Projects!$A$5:$A$9,0)) -> Site Remediation Support
A40: 46280 | B40: W-104 | C40: n/a | D40: Expense | E40: Lab analysis fees, re-billed at cost | G40: Y | H40: 2350 | I40: =INDEX(Projects!$B$5:$B$9,MATCH(B40,Projects!$A$5:$A$9,0)) -> Site Remediation Support
A41: 46283 | B41: W-102 | C41: Project Coordinator | D41: Labour | E41: Weekly time, billable | F41: 43 | G41: Y | I41: =INDEX(Projects!$B$5:$B$9,MATCH(B41,Projects!$A$5:$A$9,0)) -> Pipeline Integrity Dig Program
...

Sheet Billing
A1: SELF-DIRECTED LEARNING AND PRACTICE PROJECT. Projects, clients, hours, rates and invoices are fictional. This is a simplified illustration of work-in-progress and revenue recognition concepts for learning. It is NOT accounting work, and accounting treatment decisions belong to an accountant.
A2: Invoices and payments
A4: Invoice | B4: Invoice date | C4: Project | D4: Amount invoiced ($) | E4: Amount paid ($) | F4: Date paid | G4: Balance owing ($) | H4: Days outstanding
A5: INV-2603 | B5: 46239 | C5: W-103 | D5: 90000 | E5: 90000 | F5: 46267 | G5: =D5-E5 -> 0 | H5: =IF(G5>0,Tracker!$B$3-B5,0) -> 0
A6: INV-2604 | B6: 46246 | C6: W-105 | D6: 30000 | E6: 30000 | F6: 46283 | G6: =D6-E6 -> 0 | H6: =IF(G6>0,Tracker!$B$3-B6,0) -> 0
A7: INV-2602 | B7: 46249 | C7: W-102 | D7: 12000 | E7: 12000 | F7: 46275 | G7: =D7-E7 -> 0 | H7: =IF(G7>0,Tracker!$B$3-B7,0) -> 0
A8: INV-2601 | B8: 46262 | C8: W-101 | D8: 30000 | E8: 0 | G8: =D8-E8 -> 30000 | H8: =IF(G8>0,Tracker!$B$3-B8,0) -> 33
A9: INV-2606 | B9: 46275 | C9: W-103 | D9: 60000 | E9: 0 | G9: =D9-E9 -> 60000 | H9: =IF(G9>0,Tracker!$B$3-B9,0) -> 20
A10: INV-2605 | B10: 46280 | C10: W-102 | D10: 11400 | E10: 0 | G10: =D10-E10 -> 11400 | H10: =IF(G10>0,Tracker!$B$3-B10,0) -> 15
C11: Totals | D11: =SUM(D5:D10) -> 233400 | E11: =SUM(E5:E10) -> 132000 | G11: =SUM(G5:G10) -> 101400

Sheet Escalation
A1: SELF-DIRECTED LEARNING AND PRACTICE PROJECT. Projects, clients, hours, rates and invoices are fictional. This is a simplified illustration of work-in-progress and revenue recognition concepts for learning. It is NOT accounting work, and accounting treatment decisions belong to an accountant.
A2: What I would handle, and what I would escalate
A3: Rule of thumb: I check, calculate, flag and prepare. I do not decide accounting treatment, change contract terms or approve write-offs.
A4: Situation | B4: Next Steps | C4: Escalate to | D4: Relevant Information
A5: Time entry is missing, duplicated or at the wrong rate | B5: Run the checks, list the exceptions, ask the employee to correct | C5: Project manager if the contract rate is unclear | D5: Entry IDs, dates, rate entered vs contract rate
A6: Billable hours are not yet invoiced (unbilled WIP) | B6: Calculate the amount and the age, prepare the draft invoice data | C6: Project manager to confirm it can be billed; accountant for the accrual | D6: Project, hours, rate, amount, date of last invoice
A7: Unbilled WIP has no invoice for 45+ days | B7: Flag it on the tracker | C7: Project manager, then accountant | D7: Amount, dates of the work, last invoice date, any client approvals outstanding
A8: Invoiced amount is higher than work done (billed in excess) | B8: Show the amount and the percentage of completion used | C8: Accountant (deferred revenue treatment); project manager for progress | D8: Invoices, progress estimate, contract milestone terms
A9: Fixed-price job is near or over budget hours | B9: Flag it; do not change progress | C9: Project manager (forecast) and accountant (loss or revised estimate) | D9: Hours to date, budget hours, remaining work estimate
A10: How to measure progress on a fixed-price job | B10: Apply the method I am told to use | C10: Accountant decides the method | D10: Contract terms, available cost and hours data
A11: Client disputes an invoice or asks for a credit | B11: Record the dispute, hold related follow-up | C11: Project manager and manager; accountant for any credit memo | D11: Invoice, client message, supporting time and expense records
A12: Work done outside the contract scope (possible change order) | B12: Do not bill it; note the hours separately | C12: Project manager to confirm a change order exists | D12: Hours, descriptions, who requested the work
A13: Expense is billable or not (unclear) | B13: Check the contract and past practice | C13: Project manager; accountant for tax treatment | D13: Receipt, contract clause, amount
A14: Month-end cut-off: late timesheets or invoices | B14: Chase the timesheets, list items by project | C14: Accountant to decide what is accrued | D14: List of outstanding items with amounts
A15: Invoice unpaid 30+ days | B15: List it on the AR report and send the reminder | C15: Manager or accounting for escalation to the client | D15: Invoice, days outstanding, contact history
... A17: Anything about tax (GST, holdbacks, withholding) | B17: Note the question | C17: Accountant | D17: Invoice, contract, the specific question
